Workbook
Name ArtikelListe: OFFSET(Artikelstamm!$B$5,0,0,COUNTA(Artikelstamm!$B$5:$B$500),1)
Name Einheiten: OFFSET(Listen!$A$5,0,0,COUNTA(Listen!$A$5:$A$400),1)
Name Lagerorte: OFFSET(Listen!$B$5,0,0,COUNTA(Listen!$B$5:$B$400),1)
Name Warengruppen: OFFSET(Listen!$C$5,0,0,COUNTA(Listen!$C$5:$C$400),1)
Name Lieferanten: OFFSET(Listen!$D$5,0,0,COUNTA(Listen!$D$5:$D$400),1)
Name Zaehlstellen: OFFSET(Listen!$E$5,0,0,COUNTA(Listen!$E$5:$E$400),1)

Sheet Anleitung
A1: Inventur – Anleitung
A2: Vier Jahreszeiten Schluchsee
B4: So arbeitest du mit dieser Datei
B6: 1. Blatt „Artikelstamm“ prüfen | C6: Hier stehen alle Artikel des Hauptmagazins mit korrekter Schreibweise, Gebinde, Einheit, Lieferant und Lagerort. Prüfe und ergänze die Spalte „Lieferant“ mit deinen echten Lieferanten (Auswahl kommt aus dem Blatt „Listen“). Artikel, die ihr nicht führt, einfach löschen.
B7: 2. Zählblätter ausfüllen | C7: Für jede Zählstelle gibt es ein eigenes, leeres Blatt: Hauptmagazin, Panorama, Kachelofen, Gugelhupf, Lucia und Bar. Du füllst nur zwei Spalten aus: „Artikel“ und „Bestand (gezählt)“.
B8: 3. Artikel auswählen | C8: Klick in die Spalte „Artikel“ → rechts erscheint ein Pfeil für die Auswahlliste. Der Artikelstamm ist alphabetisch sortiert, dadurch stehen alle Varianten direkt untereinander: Coca-Cola 0,2 l Glas, Coca-Cola 0,33 l Glas, Coca-Cola 1,0 l PET, Coca-Cola light 0,2 l Glas, Coca-Cola Zero Sugar 0,2 l und 0,33 l. Du siehst die Größen also nebeneinander und wählst die richtige aus.
B9: Tipp je nach Excel-Version | C9: In Microsoft 365 filtert die Auswahlliste schon beim Tippen mit. In älteren Excel-Versionen und in LibreOffice filtert sie nicht – dort die Liste aufklappen und den Anfangsbuchstaben drücken („C“ springt zu Coca-Cola). Wer lieber tippt: im Blatt „Suche“ nachschlagen und den Namen herüberkopieren – das funktioniert in jeder Version.
B10: 4. Die Infos kommen automatisch | C10: Sobald der Artikel steht, füllen sich Warengruppe, Gebinde/Größe, Einheit und Lieferant von selbst (graue Spalten). Du musst nichts nachschlagen.
B11: 5. Überschreiben ist erlaubt | C11: Der Vorschlag ist nur ein Vorschlag. Du kannst in die Spalte „Artikel“ auch etwas ganz anderes schreiben – es kommt keine Fehlermeldung. Auch die grauen Spalten darfst du überschreiben; dann gilt dein Text statt der Automatik (nur in dieser einen Zeile).
B12: 6. Neue Artikel erkennen | C12: Steht ein Artikel noch nicht im Artikelstamm, zeigt die Spalte „Status“ automatisch „NEU – in Artikelstamm aufnehmen“. Über den Filter in der Kopfzeile kannst du alle NEU-Zeilen auf einen Blick herausfiltern.
B13: 7. Neue Artikel übernehmen | C13: Trage die neuen Artikel im Blatt „Neue Artikel“ vollständig ein (Gebinde, Einheit, Lieferant …) und kopiere die fertigen Zeilen danach unten an den Artikelstamm an. Die Auswahlliste wächst automatisch mit – sie muss nicht angepasst werden.
B14: 8. Blatt „Suche“ benutzen | C14: Wenn du nur wissen willst, welche Varianten es gibt: Im Blatt „Suche“ ein Stichwort eintippen (z. B. „cola“, „burgunder“, „wasser“, „reiniger“) – darunter erscheinen sofort alle Treffer mit Gebinde, Einheit, Inhalt, Lieferant, Warengruppe und Lagerort. Gesucht wird in Artikelname, Warengruppe und Lieferant, an beliebiger Stelle im Wort.
B15: 9. Blatt „Auswertung“ | C15: Zählt alle sechs Zählstellen je Artikel zusammen und zeigt die Gesamtsumme. Rein rechnend – hier musst du nichts eintragen.
B16: 10. Blatt „Rechtschreibung“ | C16: Nachschlagewerk mit den Schreibweisen, die erfahrungsgemäß am häufigsten falsch erfasst werden (Marken, Rebsorten, Küchenbegriffe) – jeweils mit der korrekten Form und einer kurzen Begründung.
B18: Farblegende
B20: Weiß / gelblich | C20: Felder, die du selbst ausfüllst (Artikel, Bestand, Bemerkung).
B21: Grau hinterlegt | C21: Wird automatisch gefüllt. Darfst du bei Bedarf überschreiben.
B22: Dunkelblau | C22: Überschriften – bitte nicht verändern, sonst stimmen die Formeln nicht.
B24: Wichtiger Hinweis zur Ausgangsdatei
B26: Die hochgeladene Datei war leer | C26: Die Datei „Inventur_Vier_Jahreszeiten_Schluchsee_2026-09-30_copy_2.xlsx“ enthielt nur das Grundgerüst: Kopfzeile, Spaltenüberschriften und 200 leere Zeilen, dazu die Auswahllisten für Einheiten und Lager. Es war kein einziger Artikel darin gespeichert. Der Artikelstamm in dieser Mappe ist deshalb ein fachlich recherchierter Vorschlag für ein Schwarzwald-Hotel und kein Abbild eurer tatsächlichen Bestände.
B27: Bitte gegenprüfen | C27: Vor allem die Spalten „Lieferant“, „Gebinde / Größe“ und „Inhalt je Gebinde“ sind sinnvolle Standardwerte, keine bestätigten Daten aus eurem Warenwirtschaftssystem. Die Lieferanten stehen bewusst als Kategorie („Getränkefachgroßhandel“, „Weinhandel“ …) drin – ersetze sie durch eure echten Lieferanten im Blatt „Listen“.
B28: Schreibweise der Zählstellen | C28: Korrigiert übernommen: „Kachelofen“ (mit einem f) und „Gugelhupf“. Panorama, Lucia und Bar waren bereits richtig.

Sheet Artikelstamm
A1: Artikelstamm Hauptmagazin
A2: Vier Jahreszeiten Schluchsee
A3: Alphabetisch sortiert – so stehen alle Varianten eines Artikels beieinander. Die Spalte „Artikel“ ist die Suchgrundlage für alle Zählblätter. Neue Artikel einfach unten anfügen (Reihenfolge egal, die Auswahlliste wächst automatisch mit). Über den Filter in Zeile 4 lässt sich jederzeit nach Warengruppe oder Lagerort einschränken.
A4: Art.-Nr. | B4: Artikel | C4: Warengruppe | D4: Gebinde / Größe | E4: Einheit | F4: Inhalt je Gebinde | G4: Lieferant | H4: Lagerort | I4: Bemerkung
A5: 42-006 | B5: Absolut Vodka 0,7 l | C5: Spirituosen – Gin & Wodka | D5: Flasche 0,7 l | E5: Flasche | F5: 1 Flasche | G5: Spirituosenhandel | H5: Keller | K5: =IF($B5="",0,IF(Suche!$B$4="",1,IF(ISNUMBER(SEARCH(Suche!$B$4,$B5&" "&$C5&" "&$G5)),1,0))) | L5: =IF($K5=0,"",SUM($K$5:$K5))
A6: 10-015 | B6: Acqua Panna 0,75 l Glas | C6: AFG – Mineralwasser | D6: Kasten 12 × 0,75 l | E6: Flasche | F6: 12 Flaschen/Kasten | G6: Getränkefachgroßhandel | H6: Getränkelager | K6: =IF($B6="",0,IF(Suche!$B$4="",1,IF(ISNUMBER(SEARCH(Suche!$B$4,$B6&" "&$C6&" "&$G6)),1,0))) | L6: =IF($K6=0,"",SUM($K$5:$K6))
A7: 81-001 | B7: Allzweckreiniger 1 l | C7: Housekeeping – Reinigung | D7: Flasche 1 l | E7: Flasche | F7: 1 l/Flasche | G7: Hygiene- & Reinigungsbedarf | H7: Housekeeping | K7: =IF($B7="",0,IF(Suche!$B$4="",1,IF(ISNUMBER(SEARCH(Suche!$B$4,$B7&" "&$C7&" "&$G7)),1,0))) | L7: =IF($K7=0,"",SUM($K$5:$K7))
A8: 11-020 | B8: Almdudler 0,35 l Glas | C8: AFG – Limonaden | D8: Kasten 24 × 0,35 l | E8: Flasche | F8: 24 Flaschen/Kasten | G8: Getränkefachgroßhandel | H8: Getränkelager | K8: =IF($B8="",0,IF(Suche!$B$4="",1,IF(ISNUMBER(SEARCH(Suche!$B$4,$B8&" "&$C8&" "&$G8)),1,0))) | L8: =IF($K8=0,"",SUM($K$5:$K8))
A9: 20-010 | B9: Alpirsbacher Klosterbräu Pils 0,33 l Glas | C9: Bier | D9: Kasten 24 × 0,33 l | E9: Flasche | F9: 24 Flaschen/Kasten | G9: Getränkefachgroßhandel | H9: Getränkelager | K9: =IF($B9="",0,IF(Suche!$B$4="",1,IF(ISNUMBER(SEARCH(Suche!$B$4,$B9&" "&$C9&" "&$G9)),1,0))) | L9: =IF($K9=0,"",SUM($K$5:$K9))
A10: 90-004 | B10: Alufolie 30 cm | C10: Verbrauchsmaterial Service | D10: Rolle 150 m | E10: Rolle | F10: 150 m/Rolle | G10: Lebensmittelgroßhandel | H10: Keller | K10: =IF($B10="",0,IF(Suche!$B$4="",1,IF(ISNUMBER(SEARCH(Suche!$B$4,$B10&" "&$C10&" "&$G10)),1,0))) | L10: =IF($K10=0,"",SUM($K$5:$K10))
A11: 12-006 | B11: Ananassaft 1,0 l Glas | C11: AFG – Säfte & Nektare | D11: Kasten 6 × 1,0 l | E11: Flasche | F11: 6 Flaschen/Kasten | G11: Getränkefachgroßhandel | H11: Getränkelager | K11: =IF($B11="",0,IF(Suche!$B$4="",1,IF(ISNUMBER(SEARCH(Suche!$B$4,$B11&" "&$C11&" "&$G11)),1,0))) | L11: =IF($K11=0,"",SUM($K$5:$K11))
A12: 41-007 | B12: Aperol 0,7 l | C12: Spirituosen – Bitter & Aperitif | D12: Flasche 0,7 l | E12: Flasche | F12: 1 Flasche | G12: Spirituosenhandel | H12: Keller | K12: =IF($B12="",0,IF(Suche!$B$4="",1,IF(ISNUMBER(SEARCH(Suche!$B$4,$B12&" "&$C12&" "&$G12)),1,0))) | L12: =IF($K12=0,"",SUM($K$5:$K12))
A13: 12-002 | B13: Apfelsaft klar 1,0 l Glas | C13: AFG – Säfte & Nektare | D13: Kasten 6 × 1,0 l | E13: Flasche | F13: 6 Flaschen/Kasten | G13: Getränkefachgroßhandel | H13: Getränkelager | K13: =IF($B13="",0,IF(Suche!$B$4="",1,IF(ISNUMBER(SEARCH(Suche!$B$4,$B13&" "&$C13&" "&$G13)),1,0))) | L13: =IF($K13=0,"",SUM($K$5:$K13))
A14: 12-003 | B14: Apfelsaft naturtrüb 1,0 l Glas | C14: AFG – Säfte & Nektare | D14: Kasten 6 × 1,0 l | E14: Flasche | F14: 6 Flaschen/Kasten | G14: Getränkefachgroßhandel | H14: Getränkelager | K14: =IF($B14="",0,IF(Suche!$B$4="",1,IF(ISNUMBER(SEARCH(Suche!$B$4,$B14&" "&$C14&" "&$G14)),1,0))) | L14: =IF($K14=0,"",SUM($K$5:$K14))
A15: 11-021 | B15: Apfelschorle 0,33 l Glas | C15: AFG – Limonaden | D15: Kasten 24 × 0,33 l | E15: Flasche | F15: 24 Flaschen/Kasten | G15: Getränkefachgroßhandel | H15: Getränkelager | K15: =IF($B15="",0,IF(Suche!$B$4="",1,IF(ISNUMBER(SEARCH(Suche!$B$4,$B15&" "&$C15&" "&$G15)),1,0))) | L15: =IF($K15=0,"",SUM($K$5:$K15))
A16: 11-022 | B16: Apfelschorle 0,5 l Glas | C16: AFG – Limonaden | D16: Kasten 20 × 0,5 l | E16: Flasche | F16: 20 Flaschen/Kasten | G16: Getränkefachgroßhandel | H16: Getränkelager | K16: =IF($B16="",0,IF(Suche!$B$4="",1,IF(ISNUMBER(SEARCH(Suche!$B$4,$B16&" "&$C16&" "&$G16)),1,0))) | L16: =IF($K16=0,"",SUM($K$5:$K16))
... A351: 70-032 | B351: Zwiebeln 10 kg | C351: Küche – Trockenlager | D351: Sack 10 kg | E351: kg | F351: 10 kg/Sack | G351: Lebensmittelgroßhandel | H351: Trockenlager | K351: =IF($B351="",0,IF(Suche!$B$4="",1,IF(ISNUMBER(SEARCH(Suche!$B$4,$B351&" "&$C351&" "&$G351)),1,0))) | L351: =IF($K351=0,"",SUM($K$5:$K351))
K352: =IF($B352="",0,IF(Suche!$B$4="",1,IF(ISNUMBER(SEARCH(Suche!$B$4,$B352&" "&$C352&" "&$G352)),1,0))) | L352: =IF($K352=0,"",SUM($K$5:$K352))
K353: =IF($B353="",0,IF(Suche!$B$4="",1,IF(ISNUMBER(SEARCH(Suche!$B$4,$B353&" "&$C353&" "&$G353)),1,0))) | L353: =IF($K353=0,"",SUM($K$5:$K353))
K354: =IF($B354="",0,IF(Suche!$B$4="",1,IF(ISNUMBER(SEARCH(Suche!$B$4,$B354&" "&$C354&" "&$G354)),1,0))) | L354: =IF($K354=0,"",SUM($K$5:$K354))
K355: =IF($B355="",0,IF(Suche!$B$4="",1,IF(ISNUMBER(SEARCH(Suche!$B$4,$B355&" "&$C355&" "&$G355)),1,0))) | L355: =IF($K355=0,"",SUM($K$5:$K355))
K356: =IF($B356="",0,IF(Suche!$B$4="",1,IF(ISNUMBER(SEARCH(Suche!$B$4,$B356&" "&$C356&" "&$G356)),1,0))) | L356: =IF($K356=0,"",SUM($K$5:$K356))
K357: =IF($B357="",0,IF(Suche!$B$4="",1,IF(ISNUMBER(SEARCH(Suche!$B$4,$B357&" "&$C357&" "&$G357)),1,0))) | L357: =IF($K357=0,"",SUM($K$5:$K357))
K358: =IF($B358="",0,IF(Suche!$B$4="",1,IF(ISNUMBER(SEARCH(Suche!$B$4,$B358&" "&$C358&" "&$G358)),1,0))) | L358: =IF($K358=0,"",SUM($K$5:$K358))
K359: =IF($B359="",0,IF(Suche!$B$4="",1,IF(ISNUMBER(SEARCH(Suche!$B$4,$B359&" "&$C359&" "&$G359)),1,0))) | L359: =IF($K359=0,"",SUM($K$5:$K359))
K360: =IF($B360="",0,IF(Suche!$B$4="",1,IF(ISNUMBER(SEARCH(Suche!$B$4,$B360&" "&$C360&" "&$G360)),1,0))) | L360: =IF($K360=0,"",SUM($K$5:$K360))
K361: =IF($B361="",0,IF(Suche!$B$4="",1,IF(ISNUMBER(SEARCH(Suche!$B$4,$B361&" "&$C361&" "&$G361)),1,0))) | L361: =IF($K361=0,"",SUM($K$5:$K361))
K362: =IF($B362="",0,IF(Suche!$B$4="",1,IF(ISNUMBER(SEARCH(Suche!$B$4,$B362&" "&$C362&" "&$G362)),1,0))) | L362: =IF($K362=0,"",SUM($K$5:$K362))
K363: =IF($B363="",0,IF(Suche!$B$4="",1,IF(ISNUMBER(SEARCH(Suche!$B$4,$B363&" "&$C363&" "&$G363)),1,0))) | L363: =IF($K363=0,"",SUM($K$5:$K363))
... K500: =IF($B500="",0,IF(Suche!$B$4="",1,IF(ISNUMBER(SEARCH(Suche!$B$4,$B500&" "&$C500&" "&$G500)),1,0))) | L500: =IF($K500=0,"",SUM($K$5:$K500))

Sheet Hauptmagazin
A1: Inventurliste – Hauptmagazin
A2: Vier Jahreszeiten Schluchsee
A4: Standort: | B4: Hauptmagazin
A5: Datum: | B5: 30.09.2026
A6: Aufgenommen von:
A7: Nur die Spalten „Artikel“ und „Bestand (gezählt)“ ausfüllen – in „Artikel“ einfach lostippen (z. B. „Coca“) und aus der Liste wählen. Alles andere kommt automatisch, lässt sich aber überschreiben.
A8: Artikel | B8: Warengruppe | C8: Gebinde / Größe | D8: Einheit | E8: Lieferant | F8: Bestand (gezählt) | G8: Status | H8: Bemerkung
B9: =IF($A9="","",IFERROR(VLOOKUP($A9,Artikelstamm!$B:$I,2,FALSE),"")) | C9: =IF($A9="","",IFERROR(VLOOKUP($A9,Artikelstamm!$B:$I,3,FALSE),"")) | D9: =IF($A9="","",IFERROR(VLOOKUP($A9,Artikelstamm!$B:$I,4,FALSE),"")) | E9: =IF($A9="","",IFERROR(VLOOKUP($A9,Artikelstamm!$B:$I,6,FALSE),"")) | G9: =IF($A9="","",IF(COUNTIF(Artikelstamm!$B:$B,$A9)=0,"NEU – in Artikelstamm aufnehmen","OK"))
B10: =IF($A10="","",IFERROR(VLOOKUP($A10,Artikelstamm!$B:$I,2,FALSE),"")) | C10: =IF($A10="","",IFERROR(VLOOKUP($A10,Artikelstamm!$B:$I,3,FALSE),"")) | D10: =IF($A10="","",IFERROR(VLOOKUP($A10,Artikelstamm!$B:$I,4,FALSE),"")) | E10: =IF($A10="","",IFERROR(VLOOKUP($A10,Artikelstamm!$B:$I,6,FALSE),"")) | G10: =IF($A10="","",IF(COUNTIF(Artikelstamm!$B:$B,$A10)=0,"NEU – in Artikelstamm aufnehmen","OK"))
B11: =IF($A11="","",IFERROR(VLOOKUP($A11,Artikelstamm!$B:$I,2,FALSE),"")) | C11: =IF($A11="","",IFERROR(VLOOKUP($A11,Artikelstamm!$B:$I,3,FALSE),"")) | D11: =IF($A11="","",IFERROR(VLOOKUP($A11,Artikelstamm!$B:$I,4,FALSE),"")) | E11: =IF($A11="","",IFERROR(VLOOKUP($A11,Artikelstamm!$B:$I,6,FALSE),"")) | G11: =IF($A11="","",IF(COUNTIF(Artikelstamm!$B:$B,$A11)=0,"NEU – in Artikelstamm aufnehmen","OK"))
B12: =IF($A12="","",IFERROR(VLOOKUP($A12,Artikelstamm!$B:$I,2,FALSE),"")) | C12: =IF($A12="","",IFERROR(VLOOKUP($A12,Artikelstamm!$B:$I,3,FALSE),"")) | D12: =IF($A12="","",IFERROR(VLOOKUP($A12,Artikelstamm!$B:$I,4,FALSE),"")) | E12: =IF($A12="","",IFERROR(VLOOKUP($A12,Artikelstamm!$B:$I,6,FALSE),"")) | G12: =IF($A12="","",IF(COUNTIF(Artikelstamm!$B:$B,$A12)=0,"NEU – in Artikelstamm aufnehmen","OK"))
B13: =IF($A13="","",IFERROR(VLOOKUP($A13,Artikelstamm!$B:$I,2,FALSE),"")) | C13: =IF($A13="","",IFERROR(VLOOKUP($A13,Artikelstamm!$B:$I,3,FALSE),"")) | D13: =IF($A13="","",IFERROR(VLOOKUP($A13,Artikelstamm!$B:$I,4,FALSE),"")) | E13: =IF($A13="","",IFERROR(VLOOKUP($A13,Artikelstamm!$B:$I,6,FALSE),"")) | G13: =IF($A13="","",IF(COUNTIF(Artikelstamm!$B:$B,$A13)=0,"NEU – in Artikelstamm aufnehmen","OK"))
B14: =IF($A14="","",IFERROR(VLOOKUP($A14,Artikelstamm!$B:$I,2,FALSE),"")) | C14: =IF($A14="","",IFERROR(VLOOKUP($A14,Artikelstamm!$B:$I,3,FALSE),"")) | D14: =IF($A14="","",IFERROR(VLOOKUP($A14,Artikelstamm!$B:$I,4,FALSE),"")) | E14: =IF($A14="","",IFERROR(VLOOKUP($A14,Artikelstamm!$B:$I,6,FALSE),"")) | G14: =IF($A14="","",IF(COUNTIF(Artikelstamm!$B:$B,$A14)=0,"NEU – in Artikelstamm aufnehmen","OK"))
B15: =IF($A15="","",IFERROR(VLOOKUP($A15,Artikelstamm!$B:$I,2,FALSE),"")) | C15: =IF($A15="","",IFERROR(VLOOKUP($A15,Artikelstamm!$B:$I,3,FALSE),"")) | D15: =IF($A15="","",IFERROR(VLOOKUP($A15,Artikelstamm!$B:$I,4,FALSE),"")) | E15: =IF($A15="","",IFERROR(VLOOKUP($A15,Artikelstamm!$B:$I,6,FALSE),"")) | G15: =IF($A15="","",IF(COUNTIF(Artikelstamm!$B:$B,$A15)=0,"NEU – in Artikelstamm aufnehmen","OK"))
B16: =IF($A16="","",IFERROR(VLOOKUP($A16,Artikelstamm!$B:$I,2,FALSE),"")) | C16: =IF($A16="","",IFERROR(VLOOKUP($A16,Artikelstamm!$B:$I,3,FALSE),"")) | D16: =IF($A16="","",IFERROR(VLOOKUP($A16,Artikelstamm!$B:$I,4,FALSE),"")) | E16: =IF($A16="","",IFERROR(VLOOKUP($A16,Artikelstamm!$B:$I,6,FALSE),"")) | G16: =IF($A16="","",IF(COUNTIF(Artikelstamm!$B:$B,$A16)=0,"NEU – in Artikelstamm aufnehmen","OK"))
B17: =IF($A17="","",IFERROR(VLOOKUP($A17,Artikelstamm!$B:$I,2,FALSE),"")) | C17: =IF($A17="","",IFERROR(VLOOKUP($A17,Artikelstamm!$B:$I,3,FALSE),"")) | D17: =IF($A17="","",IFERROR(VLOOKUP($A17,Artikelstamm!$B:$I,4,FALSE),"")) | E17: =IF($A17="","",IFERROR(VLOOKUP($A17,Artikelstamm!$B:$I,6,FALSE),"")) | G17: =IF($A17="","",IF(COUNTIF(Artikelstamm!$B:$B,$A17)=0,"NEU – in Artikelstamm aufnehmen","OK"))
B18: =IF($A18="","",IFERROR(VLOOKUP($A18,Artikelstamm!$B:$I,2,FALSE),"")) | C18: =IF($A18="","",IFERROR(VLOOKUP($A18,Artikelstamm!$B:$I,3,FALSE),"")) | D18: =IF($A18="","",IFERROR(VLOOKUP($A18,Artikelstamm!$B:$I,4,FALSE),"")) | E18: =IF($A18="","",IFERROR(VLOOKUP($A18,Artikelstamm!$B:$I,6,FALSE),"")) | G18: =IF($A18="","",IF(COUNTIF(Artikelstamm!$B:$B,$A18)=0,"NEU – in Artikelstamm aufnehmen","OK"))
B19: =IF($A19="","",IFERROR(VLOOKUP($A19,Artikelstamm!$B:$I,2,FALSE),"")) | C19: =IF($A19="","",IFERROR(VLOOKUP($A19,Artikelstamm!$B:$I,3,FALSE),"")) | D19: =IF($A19="","",IFERROR(VLOOKUP($A19,Artikelstamm!$B:$I,4,FALSE),"")) | E19: =IF($A19="","",IFERROR(VLOOKUP($A19,Artikelstamm!$B:$I,6,FALSE),"")) | G19: =IF($A19="","",IF(COUNTIF(Artikelstamm!$B:$B,$A19)=0,"NEU – in Artikelstamm aufnehmen","OK"))
B20: =IF($A20="","",IFERROR(VLOOKUP($A20,Artikelstamm!$B:$I,2,FALSE),"")) | C20: =IF($A20="","",IFERROR(VLOOKUP($A20,Artikelstamm!$B:$I,3,FALSE),"")) | D20: =IF($A20="","",IFERROR(VLOOKUP($A20,Artikelstamm!$B:$I,4,FALSE),"")) | E20: =IF($A20="","",IFERROR(VLOOKUP($A20,Artikelstamm!$B:$I,6,FALSE),"")) | G20: =IF($A20="","",IF(COUNTIF(Artikelstamm!$B:$B,$A20)=0,"NEU – in Artikelstamm aufnehmen","OK"))
... B258: =IF($A258="","",IFERROR(VLOOKUP($A258,Artikelstamm!$B:$I,2,FALSE),"")) | C258: =IF($A258="","",IFERROR(VLOOKUP($A258,Artikelstamm!$B:$I,3,FALSE),"")) | D258: =IF($A258="","",IFERROR(VLOOKUP($A258,Artikelstamm!$B:$I,4,FALSE),"")) | E258: =IF($A258="","",IFERROR(VLOOKUP($A258,Artikelstamm!$B:$I,6,FALSE),"")) | G258: =IF($A258="","",IF(COUNTIF(Artikelstamm!$B:$B,$A258)=0,"NEU – in Artikelstamm aufnehmen","OK"))

Sheet Panorama
A1: Inventurliste – Panorama
A2: Vier Jahreszeiten Schluchsee
A4: Standort: | B4: Panorama
A5: Datum: | B5: 30.09.2026
A6: Aufgenommen von:
A7: Nur die Spalten „Artikel“ und „Bestand (gezählt)“ ausfüllen – in „Artikel“ einfach lostippen (z. B. „Coca“) und aus der Liste wählen. Alles andere kommt automatisch, lässt sich aber überschreiben.
A8: Artikel | B8: Warengruppe | C8: Gebinde / Größe | D8: Einheit | E8: Lieferant | F8: Bestand (gezählt) | G8: Status | H8: Bemerkung
B9: =IF($A9="","",IFERROR(VLOOKUP($A9,Artikelstamm!$B:$I,2,FALSE),"")) | C9: =IF($A9="","",IFERROR(VLOOKUP($A9,Artikelstamm!$B:$I,3,FALSE),"")) | D9: =IF($A9="","",IFERROR(VLOOKUP($A9,Artikelstamm!$B:$I,4,FALSE),"")) | E9: =IF($A9="","",IFERROR(VLOOKUP($A9,Artikelstamm!$B:$I,6,FALSE),"")) | G9: =IF($A9="","",IF(COUNTIF(Artikelstamm!$B:$B,$A9)=0,"NEU – in Artikelstamm aufnehmen","OK"))
B10: =IF($A10="","",IFERROR(VLOOKUP($A10,Artikelstamm!$B:$I,2,FALSE),"")) | C10: =IF($A10="","",IFERROR(VLOOKUP($A10,Artikelstamm!$B:$I,3,FALSE),"")) | D10: =IF($A10="","",IFERROR(VLOOKUP($A10,Artikelstamm!$B:$I,4,FALSE),"")) | E10: =IF($A10="","",IFERROR(VLOOKUP($A10,Artikelstamm!$B:$I,6,FALSE),"")) | G10: =IF($A10="","",IF(COUNTIF(Artikelstamm!$B:$B,$A10)=0,"NEU – in Artikelstamm aufnehmen","OK"))
B11: =IF($A11="","",IFERROR(VLOOKUP($A11,Artikelstamm!$B:$I,2,FALSE),"")) | C11: =IF($A11="","",IFERROR(VLOOKUP($A11,Artikelstamm!$B:$I,3,FALSE),"")) | D11: =IF($A11="","",IFERROR(VLOOKUP($A11,Artikelstamm!$B:$I,4,FALSE),"")) | E11: =IF($A11="","",IFERROR(VLOOKUP($A11,Artikelstamm!$B:$I,6,FALSE),"")) | G11: =IF($A11="","",IF(COUNTIF(Artikelstamm!$B:$B,$A11)=0,"NEU – in Artikelstamm aufnehmen","OK"))
B12: =IF($A12="","",IFERROR(VLOOKUP($A12,Artikelstamm!$B:$I,2,FALSE),"")) | C12: =IF($A12="","",IFERROR(VLOOKUP($A12,Artikelstamm!$B:$I,3,FALSE),"")) | D12: =IF($A12="","",IFERROR(VLOOKUP($A12,Artikelstamm!$B:$I,4,FALSE),"")) | E12: =IF($A12="","",IFERROR(VLOOKUP($A12,Artikelstamm!$B:$I,6,FALSE),"")) | G12: =IF($A12="","",IF(COUNTIF(Artikelstamm!$B:$B,$A12)=0,"NEU – in Artikelstamm aufnehmen","OK"))
B13: =IF($A13="","",IFERROR(VLOOKUP($A13,Artikelstamm!$B:$I,2,FALSE),"")) | C13: =IF($A13="","",IFERROR(VLOOKUP($A13,Artikelstamm!$B:$I,3,FALSE),"")) | D13: =IF($A13="","",IFERROR(VLOOKUP($A13,Artikelstamm!$B:$I,4,FALSE),"")) | E13: =IF($A13="","",IFERROR(VLOOKUP($A13,Artikelstamm!$B:$I,6,FALSE),"")) | G13: =IF($A13="","",IF(COUNTIF(Artikelstamm!$B:$B,$A13)=0,"NEU – in Artikelstamm aufnehmen","OK"))
B14: =IF($A14="","",IFERROR(VLOOKUP($A14,Artikelstamm!$B:$I,2,FALSE),"")) | C14: =IF($A14="","",IFERROR(VLOOKUP($A14,Artikelstamm!$B:$I,3,FALSE),"")) | D14: =IF($A14="","",IFERROR(VLOOKUP($A14,Artikelstamm!$B:$I,4,FALSE),"")) | E14: =IF($A14="","",IFERROR(VLOOKUP($A14,Artikelstamm!$B:$I,6,FALSE),"")) | G14: =IF($A14="","",IF(COUNTIF(Artikelstamm!$B:$B,$A14)=0,"NEU – in Artikelstamm aufnehmen","OK"))
B15: =IF($A15="","",IFERROR(VLOOKUP($A15,Artikelstamm!$B:$I,2,FALSE),"")) | C15: =IF($A15="","",IFERROR(VLOOKUP($A15,Artikelstamm!$B:$I,3,FALSE),"")) | D15: =IF($A15="","",IFERROR(VLOOKUP($A15,Artikelstamm!$B:$I,4,FALSE),"")) | E15: =IF($A15="","",IFERROR(VLOOKUP($A15,Artikelstamm!$B:$I,6,FALSE),"")) | G15: =IF($A15="","",IF(COUNTIF(Artikelstamm!$B:$B,$A15)=0,"NEU – in Artikelstamm aufnehmen","OK"))
B16: =IF($A16="","",IFERROR(VLOOKUP($A16,Artikelstamm!$B:$I,2,FALSE),"")) | C16: =IF($A16="","",IFERROR(VLOOKUP($A16,Artikelstamm!$B:$I,3,FALSE),"")) | D16: =IF($A16="","",IFERROR(VLOOKUP($A16,Artikelstamm!$B:$I,4,FALSE),"")) | E16: =IF($A16="","",IFERROR(VLOOKUP($A16,Artikelstamm!$B:$I,6,FALSE),"")) | G16: =IF($A16="","",IF(COUNTIF(Artikelstamm!$B:$B,$A16)=0,"NEU – in Artikelstamm aufnehmen","OK"))
B17: =IF($A17="","",IFERROR(VLOOKUP($A17,Artikelstamm!$B:$I,2,FALSE),"")) | C17: =IF($A17="","",IFERROR(VLOOKUP($A17,Artikelstamm!$B:$I,3,FALSE),"")) | D17: =IF($A17="","",IFERROR(VLOOKUP($A17,Artikelstamm!$B:$I,4,FALSE),"")) | E17: =IF($A17="","",IFERROR(VLOOKUP($A17,Artikelstamm!$B:$I,6,FALSE),"")) | G17: =IF($A17="","",IF(COUNTIF(Artikelstamm!$B:$B,$A17)=0,"NEU – in Artikelstamm aufnehmen","OK"))
B18: =IF($A18="","",IFERROR(VLOOKUP($A18,Artikelstamm!$B:$I,2,FALSE),"")) | C18: =IF($A18="","",IFERROR(VLOOKUP($A18,Artikelstamm!$B:$I,3,FALSE),"")) | D18: =IF($A18="","",IFERROR(VLOOKUP($A18,Artikelstamm!$B:$I,4,FALSE),"")) | E18: =IF($A18="","",IFERROR(VLOOKUP($A18,Artikelstamm!$B:$I,6,FALSE),"")) | G18: =IF($A18="","",IF(COUNTIF(Artikelstamm!$B:$B,$A18)=0,"NEU – in Artikelstamm aufnehmen","OK"))
B19: =IF($A19="","",IFERROR(VLOOKUP($A19,Artikelstamm!$B:$I,2,FALSE),"")) | C19: =IF($A19="","",IFERROR(VLOOKUP($A19,Artikelstamm!$B:$I,3,FALSE),"")) | D19: =IF($A19="","",IFERROR(VLOOKUP($A19,Artikelstamm!$B:$I,4,FALSE),"")) | E19: =IF($A19="","",IFERROR(VLOOKUP($A19,Artikelstamm!$B:$I,6,FALSE),"")) | G19: =IF($A19="","",IF(COUNTIF(Artikelstamm!$B:$B,$A19)=0,"NEU – in Artikelstamm aufnehmen","OK"))
B20: =IF($A20="","",IFERROR(VLOOKUP($A20,Artikelstamm!$B:$I,2,FALSE),"")) | C20: =IF($A20="","",IFERROR(VLOOKUP($A20,Artikelstamm!$B:$I,3,FALSE),"")) | D20: =IF($A20="","",IFERROR(VLOOKUP($A20,Artikelstamm!$B:$I,4,FALSE),"")) | E20: =IF($A20="","",IFERROR(VLOOKUP($A20,Artikelstamm!$B:$I,6,FALSE),"")) | G20: =IF($A20="","",IF(COUNTIF(Artikelstamm!$B:$B,$A20)=0,"NEU – in Artikelstamm aufnehmen","OK"))
... B258: =IF($A258="","",IFERROR(VLOOKUP($A258,Artikelstamm!$B:$I,2,FALSE),"")) | C258: =IF($A258="","",IFERROR(VLOOKUP($A258,Artikelstamm!$B:$I,3,FALSE),"")) | D258: =IF($A258="","",IFERROR(VLOOKUP($A258,Artikelstamm!$B:$I,4,FALSE),"")) | E258: =IF($A258="","",IFERROR(VLOOKUP($A258,Artikelstamm!$B:$I,6,FALSE),"")) | G258: =IF($A258="","",IF(COUNTIF(Artikelstamm!$B:$B,$A258)=0,"NEU – in Artikelstamm aufnehmen","OK"))

Sheet Kachelofen
A1: Inventurliste – Kachelofen
A2: Vier Jahreszeiten Schluchsee
A4: Standort: | B4: Kachelofen
A5: Datum: | B5: 30.09.2026
A6: Aufgenommen von:
A7: Nur die Spalten „Artikel“ und „Bestand (gezählt)“ ausfüllen – in „Artikel“ einfach lostippen (z. B. „Coca“) und aus der Liste wählen. Alles andere kommt automatisch, lässt sich aber überschreiben.
A8: Artikel | B8: Warengruppe | C8: Gebinde / Größe | D8: Einheit | E8: Lieferant | F8: Bestand (gezählt) | G8: Status | H8: Bemerkung
B9: =IF($A9="","",IFERROR(VLOOKUP($A9,Artikelstamm!$B:$I,2,FALSE),"")) | C9: =IF($A9="","",IFERROR(VLOOKUP($A9,Artikelstamm!$B:$I,3,FALSE),"")) | D9: =IF($A9="","",IFERROR(VLOOKUP($A9,Artikelstamm!$B:$I,4,FALSE),"")) | E9: =IF($A9="","",IFERROR(VLOOKUP($A9,Artikelstamm!$B:$I,6,FALSE),"")) | G9: =IF($A9="","",IF(COUNTIF(Artikelstamm!$B:$B,$A9)=0,"NEU – in Artikelstamm aufnehmen","OK"))
B10: =IF($A10="","",IFERROR(VLOOKUP($A10,Artikelstamm!$B:$I,2,FALSE),"")) | C10: =IF($A10="","",IFERROR(VLOOKUP($A10,Artikelstamm!$B:$I,3,FALSE),"")) | D10: =IF($A10="","",IFERROR(VLOOKUP($A10,Artikelstamm!$B:$I,4,FALSE),"")) | E10: =IF($A10="","",IFERROR(VLOOKUP($A10,Artikelstamm!$B:$I,6,FALSE),"")) | G10: =IF($A10="","",IF(COUNTIF(Artikelstamm!$B:$B,$A10)=0,"NEU – in Artikelstamm aufnehmen","OK"))
B11: =IF($A11="","",IFERROR(VLOOKUP($A11,Artikelstamm!$B:$I,2,FALSE),"")) | C11: =IF($A11="","",IFERROR(VLOOKUP($A11,Artikelstamm!$B:$I,3,FALSE),"")) | D11: =IF($A11="","",IFERROR(VLOOKUP($A11,Artikelstamm!$B:$I,4,FALSE),"")) | E11: =IF($A11="","",IFERROR(VLOOKUP($A11,Artikelstamm!$B:$I,6,FALSE),"")) | G11: =IF($A11="","",IF(COUNTIF(Artikelstamm!$B:$B,$A11)=0,"NEU – in Artikelstamm aufnehmen","OK"))
B12: =IF($A12="","",IFERROR(VLOOKUP($A12,Artikelstamm!$B:$I,2,FALSE),"")) | C12: =IF($A12="","",IFERROR(VLOOKUP($A12,Artikelstamm!$B:$I,3,FALSE),"")) | D12: =IF($A12="","",IFERROR(VLOOKUP($A12,Artikelstamm!$B:$I,4,FALSE),"")) | E12: =IF($A12="","",IFERROR(VLOOKUP($A12,Artikelstamm!$B:$I,6,FALSE),"")) | G12: =IF($A12="","",IF(COUNTIF(Artikelstamm!$B:$B,$A12)=0,"NEU – in Artikelstamm aufnehmen","OK"))
B13: =IF($A13="","",IFERROR(VLOOKUP($A13,Artikelstamm!$B:$I,2,FALSE),"")) | C13: =IF($A13="","",IFERROR(VLOOKUP($A13,Artikelstamm!$B:$I,3,FALSE),"")) | D13: =IF($A13="","",IFERROR(VLOOKUP($A13,Artikelstamm!$B:$I,4,FALSE),"")) | E13: =IF($A13="","",IFERROR(VLOOKUP($A13,Artikelstamm!$B:$I,6,FALSE),"")) | G13: =IF($A13="","",IF(COUNTIF(Artikelstamm!$B:$B,$A13)=0,"NEU – in Artikelstamm aufnehmen","OK"))
B14: =IF($A14="","",IFERROR(VLOOKUP($A14,Artikelstamm!$B:$I,2,FALSE),"")) | C14: =IF($A14="","",IFERROR(VLOOKUP($A14,Artikelstamm!$B:$I,3,FALSE),"")) | D14: =IF($A14="","",IFERROR(VLOOKUP($A14,Artikelstamm!$B:$I,4,FALSE),"")) | E14: =IF($A14="","",IFERROR(VLOOKUP($A14,Artikelstamm!$B:$I,6,FALSE),"")) | G14: =IF($A14="","",IF(COUNTIF(Artikelstamm!$B:$B,$A14)=0,"NEU – in Artikelstamm aufnehmen","OK"))
B15: =IF($A15="","",IFERROR(VLOOKUP($A15,Artikelstamm!$B:$I,2,FALSE),"")) | C15: =IF($A15="","",IFERROR(VLOOKUP($A15,Artikelstamm!$B:$I,3,FALSE),"")) | D15: =IF($A15="","",IFERROR(VLOOKUP($A15,Artikelstamm!$B:$I,4,FALSE),"")) | E15: =IF($A15="","",IFERROR(VLOOKUP($A15,Artikelstamm!$B:$I,6,FALSE),"")) | G15: =IF($A15="","",IF(COUNTIF(Artikelstamm!$B:$B,$A15)=0,"NEU – in Artikelstamm aufnehmen","OK"))
B16: =IF($A16="","",IFERROR(VLOOKUP($A16,Artikelstamm!$B:$I,2,FALSE),"")) | C16: =IF($A16="","",IFERROR(VLOOKUP($A16,Artikelstamm!$B:$I,3,FALSE),"")) | D16: =IF($A16="","",IFERROR(VLOOKUP($A16,Artikelstamm!$B:$I,4,FALSE),"")) | E16: =IF($A16="","",IFERROR(VLOOKUP($A16,Artikelstamm!$B:$I,6,FALSE),"")) | G16: =IF($A16="","",IF(COUNTIF(Artikelstamm!$B:$B,$A16)=0,"NEU – in Artikelstamm aufnehmen","OK"))
B17: =IF($A17="","",IFERROR(VLOOKUP($A17,Artikelstamm!$B:$I,2,FALSE),"")) | C17: =IF($A17="","",IFERROR(VLOOKUP($A17,Artikelstamm!$B:$I,3,FALSE),"")) | D17: =IF($A17="","",IFERROR(VLOOKUP($A17,Artikelstamm!$B:$I,4,FALSE),"")) | E17: =IF($A17="","",IFERROR(VLOOKUP($A17,Artikelstamm!$B:$I,6,FALSE),"")) | G17: =IF($A17="","",IF(COUNTIF(Artikelstamm!$B:$B,$A17)=0,"NEU – in Artikelstamm aufnehmen","OK"))
B18: =IF($A18="","",IFERROR(VLOOKUP($A18,Artikelstamm!$B:$I,2,FALSE),"")) | C18: =IF($A18="","",IFERROR(VLOOKUP($A18,Artikelstamm!$B:$I,3,FALSE),"")) | D18: =IF($A18="","",IFERROR(VLOOKUP($A18,Artikelstamm!$B:$I,4,FALSE),"")) | E18: =IF($A18="","",IFERROR(VLOOKUP($A18,Artikelstamm!$B:$I,6,FALSE),"")) | G18: =IF($A18="","",IF(COUNTIF(Artikelstamm!$B:$B,$A18)=0,"NEU – in Artikelstamm aufnehmen","OK"))
B19: =IF($A19="","",IFERROR(VLOOKUP($A19,Artikelstamm!$B:$I,2,FALSE),"")) | C19: =IF($A19="","",IFERROR(VLOOKUP($A19,Artikelstamm!$B:$I,3,FALSE),"")) | D19: =IF($A19="","",IFERROR(VLOOKUP($A19,Artikelstamm!$B:$I,4,FALSE),"")) | E19: =IF($A19="","",IFERROR(VLOOKUP($A19,Artikelstamm!$B:$I,6,FALSE),"")) | G19: =IF($A19="","",IF(COUNTIF(Artikelstamm!$B:$B,$A19)=0,"NEU – in Artikelstamm aufnehmen","OK"))
B20: =IF($A20="","",IFERROR(VLOOKUP($A20,Artikelstamm!$B:$I,2,FALSE),"")) | C20: =IF($A20="","",IFERROR(VLOOKUP($A20,Artikelstamm!$B:$I,3,FALSE),"")) | D20: =IF($A20="","",IFERROR(VLOOKUP($A20,Artikelstamm!$B:$I,4,FALSE),"")) | E20: =IF($A20="","",IFERROR(VLOOKUP($A20,Artikelstamm!$B:$I,6,FALSE),"")) | G20: =IF($A20="","",IF(COUNTIF(Artikelstamm!$B:$B,$A20)=0,"NEU – in Artikelstamm aufnehmen","OK"))
... B258: =IF($A258="","",IFERROR(VLOOKUP($A258,Artikelstamm!$B:$I,2,FALSE),"")) | C258: =IF($A258="","",IFERROR(VLOOKUP($A258,Artikelstamm!$B:$I,3,FALSE),"")) | D258: =IF($A258="","",IFERROR(VLOOKUP($A258,Artikelstamm!$B:$I,4,FALSE),"")) | E258: =IF($A258="","",IFERROR(VLOOKUP($A258,Artikelstamm!$B:$I,6,FALSE),"")) | G258: =IF($A258="","",IF(COUNTIF(Artikelstamm!$B:$B,$A258)=0,"NEU – in Artikelstamm aufnehmen","OK"))

Sheet Gugelhupf
A1: Inventurliste – Gugelhupf
A2: Vier Jahreszeiten Schluchsee
A4: Standort: | B4: Gugelhupf
A5: Datum: | B5: 30.09.2026
A6: Aufgenommen von:
A7: Nur die Spalten „Artikel“ und „Bestand (gezählt)“ ausfüllen – in „Artikel“ einfach lostippen (z. B. „Coca“) und aus der Liste wählen. Alles andere kommt automatisch, lässt sich aber überschreiben.
A8: Artikel | B8: Warengruppe | C8: Gebinde / Größe | D8: Einheit | E8: Lieferant | F8: Bestand (gezählt) | G8: Status | H8: Bemerkung
B9: =IF($A9="","",IFERROR(VLOOKUP($A9,Artikelstamm!$B:$I,2,FALSE),"")) | C9: =IF($A9="","",IFERROR(VLOOKUP($A9,Artikelstamm!$B:$I,3,FALSE),"")) | D9: =IF($A9="","",IFERROR(VLOOKUP($A9,Artikelstamm!$B:$I,4,FALSE),"")) | E9: =IF($A9="","",IFERROR(VLOOKUP($A9,Artikelstamm!$B:$I,6,FALSE),"")) | G9: =IF($A9="","",IF(COUNTIF(Artikelstamm!$B:$B,$A9)=0,"NEU – in Artikelstamm aufnehmen","OK"))
B10: =IF($A10="","",IFERROR(VLOOKUP($A10,Artikelstamm!$B:$I,2,FALSE),"")) | C10: =IF($A10="","",IFERROR(VLOOKUP($A10,Artikelstamm!$B:$I,3,FALSE),"")) | D10: =IF($A10="","",IFERROR(VLOOKUP($A10,Artikelstamm!$B:$I,4,FALSE),"")) | E10: =IF($A10="","",IFERROR(VLOOKUP($A10,Artikelstamm!$B:$I,6,FALSE),"")) | G10: =IF($A10="","",IF(COUNTIF(Artikelstamm!$B:$B,$A10)=0,"NEU – in Artikelstamm aufnehmen","OK"))
B11: =IF($A11="","",IFERROR(VLOOKUP($A11,Artikelstamm!$B:$I,2,FALSE),"")) | C11: =IF($A11="","",IFERROR(VLOOKUP($A11,Artikelstamm!$B:$I,3,FALSE),"")) | D11: =IF($A11="","",IFERROR(VLOOKUP($A11,Artikelstamm!$B:$I,4,FALSE),"")) | E11: =IF($A11="","",IFERROR(VLOOKUP($A11,Artikelstamm!$B:$I,6,FALSE),"")) | G11: =IF($A11="","",IF(COUNTIF(Artikelstamm!$B:$B,$A11)=0,"NEU – in Artikelstamm aufnehmen","OK"))
B12: =IF($A12="","",IFERROR(VLOOKUP($A12,Artikelstamm!$B:$I,2,FALSE),"")) | C12: =IF($A12="","",IFERROR(VLOOKUP($A12,Artikelstamm!$B:$I,3,FALSE),"")) | D12: =IF($A12="","",IFERROR(VLOOKUP($A12,Artikelstamm!$B:$I,4,FALSE),"")) | E12: =IF($A12="","",IFERROR(VLOOKUP($A12,Artikelstamm!$B:$I,6,FALSE),"")) | G12: =IF($A12="","",IF(COUNTIF(Artikelstamm!$B:$B,$A12)=0,"NEU – in Artikelstamm aufnehmen","OK"))
B13: =IF($A13="","",IFERROR(VLOOKUP($A13,Artikelstamm!$B:$I,2,FALSE),"")) | C13: =IF($A13="","",IFERROR(VLOOKUP($A13,Artikelstamm!$B:$I,3,FALSE),"")) | D13: =IF($A13="","",IFERROR(VLOOKUP($A13,Artikelstamm!$B:$I,4,FALSE),"")) | E13: =IF($A13="","",IFERROR(VLOOKUP($A13,Artikelstamm!$B:$I,6,FALSE),"")) | G13: =IF($A13="","",IF(COUNTIF(Artikelstamm!$B:$B,$A13)=0,"NEU – in Artikelstamm aufnehmen","OK"))
B14: =IF($A14="","",IFERROR(VLOOKUP($A14,Artikelstamm!$B:$I,2,FALSE),"")) | C14: =IF($A14="","",IFERROR(VLOOKUP($A14,Artikelstamm!$B:$I,3,FALSE),"")) | D14: =IF($A14="","",IFERROR(VLOOKUP($A14,Artikelstamm!$B:$I,4,FALSE),"")) | E14: =IF($A14="","",IFERROR(VLOOKUP($A14,Artikelstamm!$B:$I,6,FALSE),"")) | G14: =IF($A14="","",IF(COUNTIF(Artikelstamm!$B:$B,$A14)=0,"NEU – in Artikelstamm aufnehmen","OK"))
B15: =IF($A15="","",IFERROR(VLOOKUP($A15,Artikelstamm!$B:$I,2,FALSE),"")) | C15: =IF($A15="","",IFERROR(VLOOKUP($A15,Artikelstamm!$B:$I,3,FALSE),"")) | D15: =IF($A15="","",IFERROR(VLOOKUP($A15,Artikelstamm!$B:$I,4,FALSE),"")) | E15: =IF($A15="","",IFERROR(VLOOKUP($A15,Artikelstamm!$B:$I,6,FALSE),"")) | G15: =IF($A15="","",IF(COUNTIF(Artikelstamm!$B:$B,$A15)=0,"NEU – in Artikelstamm aufnehmen","OK"))
B16: =IF($A16="","",IFERROR(VLOOKUP($A16,Artikelstamm!$B:$I,2,FALSE),"")) | C16: =IF($A16="","",IFERROR(VLOOKUP($A16,Artikelstamm!$B:$I,3,FALSE),"")) | D16: =IF($A16="","",IFERROR(VLOOKUP($A16,Artikelstamm!$B:$I,4,FALSE),"")) | E16: =IF($A16="","",IFERROR(VLOOKUP($A16,Artikelstamm!$B:$I,6,FALSE),"")) | G16: =IF($A16="","",IF(COUNTIF(Artikelstamm!$B:$B,$A16)=0,"NEU – in Artikelstamm aufnehmen","OK"))
B17: =IF($A17="","",IFERROR(VLOOKUP($A17,Artikelstamm!$B:$I,2,FALSE),"")) | C17: =IF($A17="","",IFERROR(VLOOKUP($A17,Artikelstamm!$B:$I,3,FALSE),"")) | D17: =IF($A17="","",IFERROR(VLOOKUP($A17,Artikelstamm!$B:$I,4,FALSE),"")) | E17: =IF($A17="","",IFERROR(VLOOKUP($A17,Artikelstamm!$B:$I,6,FALSE),"")) | G17: =IF($A17="","",IF(COUNTIF(Artikelstamm!$B:$B,$A17)=0,"NEU – in Artikelstamm aufnehmen","OK"))
B18: =IF($A18="","",IFERROR(VLOOKUP($A18,Artikelstamm!$B:$I,2,FALSE),"")) | C18: =IF($A18="","",IFERROR(VLOOKUP($A18,Artikelstamm!$B:$I,3,FALSE),"")) | D18: =IF($A18="","",IFERROR(VLOOKUP($A18,Artikelstamm!$B:$I,4,FALSE),"")) | E18: =IF($A18="","",IFERROR(VLOOKUP($A18,Artikelstamm!$B:$I,6,FALSE),"")) | G18: =IF($A18="","",IF(COUNTIF(Artikelstamm!$B:$B,$A18)=0,"NEU – in Artikelstamm aufnehmen","OK"))
B19: =IF($A19="","",IFERROR(VLOOKUP($A19,Artikelstamm!$B:$I,2,FALSE),"")) | C19: =IF($A19="","",IFERROR(VLOOKUP($A19,Artikelstamm!$B:$I,3,FALSE),"")) | D19: =IF($A19="","",IFERROR(VLOOKUP($A19,Artikelstamm!$B:$I,4,FALSE),"")) | E19: =IF($A19="","",IFERROR(VLOOKUP($A19,Artikelstamm!$B:$I,6,FALSE),"")) | G19: =IF($A19="","",IF(COUNTIF(Artikelstamm!$B:$B,$A19)=0,"NEU – in Artikelstamm aufnehmen","OK"))
B20: =IF($A20="","",IFERROR(VLOOKUP($A20,Artikelstamm!$B:$I,2,FALSE),"")) | C20: =IF($A20="","",IFERROR(VLOOKUP($A20,Artikelstamm!$B:$I,3,FALSE),"")) | D20: =IF($A20="","",IFERROR(VLOOKUP($A20,Artikelstamm!$B:$I,4,FALSE),"")) | E20: =IF($A20="","",IFERROR(VLOOKUP($A20,Artikelstamm!$B:$I,6,FALSE),"")) | G20: =IF($A20="","",IF(COUNTIF(Artikelstamm!$B:$B,$A20)=0,"NEU – in Artikelstamm aufnehmen","OK"))
... B258: =IF($A258="","",IFERROR(VLOOKUP($A258,Artikelstamm!$B:$I,2,FALSE),"")) | C258: =IF($A258="","",IFERROR(VLOOKUP($A258,Artikelstamm!$B:$I,3,FALSE),"")) | D258: =IF($A258="","",IFERROR(VLOOKUP($A258,Artikelstamm!$B:$I,4,FALSE),"")) | E258: =IF($A258="","",IFERROR(VLOOKUP($A258,Artikelstamm!$B:$I,6,FALSE),"")) | G258: =IF($A258="","",IF(COUNTIF(Artikelstamm!$B:$B,$A258)=0,"NEU – in Artikelstamm aufnehmen","OK"))

Sheet Lucia
A1: Inventurliste – Lucia
A2: Vier Jahreszeiten Schluchsee
A4: Standort: | B4: Lucia
A5: Datum: | B5: 30.09.2026
A6: Aufgenommen von:
A7: Nur die Spalten „Artikel“ und „Bestand (gezählt)“ ausfüllen – in „Artikel“ einfach lostippen (z. B. „Coca“) und aus der Liste wählen. Alles andere kommt automatisch, lässt sich aber überschreiben.
A8: Artikel | B8: Warengruppe | C8: Gebinde / Größe | D8: Einheit | E8: Lieferant | F8: Bestand (gezählt) | G8: Status | H8: Bemerkung
B9: =IF($A9="","",IFERROR(VLOOKUP($A9,Artikelstamm!$B:$I,2,FALSE),"")) | C9: =IF($A9="","",IFERROR(VLOOKUP($A9,Artikelstamm!$B:$I,3,FALSE),"")) | D9: =IF($A9="","",IFERROR(VLOOKUP($A9,Artikelstamm!$B:$I,4,FALSE),"")) | E9: =IF($A9="","",IFERROR(VLOOKUP($A9,Artikelstamm!$B:$I,6,FALSE),"")) | G9: =IF($A9="","",IF(COUNTIF(Artikelstamm!$B:$B,$A9)=0,"NEU – in Artikelstamm aufnehmen","OK"))
B10: =IF($A10="","",IFERROR(VLOOKUP($A10,Artikelstamm!$B:$I,2,FALSE),"")) | C10: =IF($A10="","",IFERROR(VLOOKUP($A10,Artikelstamm!$B:$I,3,FALSE),"")) | D10: =IF($A10="","",IFERROR(VLOOKUP($A10,Artikelstamm!$B:$I,4,FALSE),"")) | E10: =IF($A10="","",IFERROR(VLOOKUP($A10,Artikelstamm!$B:$I,6,FALSE),"")) | G10: =IF($A10="","",IF(COUNTIF(Artikelstamm!$B:$B,$A10)=0,"NEU – in Artikelstamm aufnehmen","OK"))
B11: =IF($A11="","",IFERROR(VLOOKUP($A11,Artikelstamm!$B:$I,2,FALSE),"")) | C11: =IF($A11="","",IFERROR(VLOOKUP($A11,Artikelstamm!$B:$I,3,FALSE),"")) | D11: =IF($A11="","",IFERROR(VLOOKUP($A11,Artikelstamm!$B:$I,4,FALSE),"")) | E11: =IF($A11="","",IFERROR(VLOOKUP($A11,Artikelstamm!$B:$I,6,FALSE),"")) | G11: =IF($A11="","",IF(COUNTIF(Artikelstamm!$B:$B,$A11)=0,"NEU – in Artikelstamm aufnehmen","OK"))
B12: =IF($A12="","",IFERROR(VLOOKUP($A12,Artikelstamm!$B:$I,2,FALSE),"")) | C12: =IF($A12="","",IFERROR(VLOOKUP($A12,Artikelstamm!$B:$I,3,FALSE),"")) | D12: =IF($A12="","",IFERROR(VLOOKUP($A12,Artikelstamm!$B:$I,4,FALSE),"")) | E12: =IF($A12="","",IFERROR(VLOOKUP($A12,Artikelstamm!$B:$I,6,FALSE),"")) | G12: =IF($A12="","",IF(COUNTIF(Artikelstamm!$B:$B,$A12)=0,"NEU – in Artikelstamm aufnehmen","OK"))
B13: =IF($A13="","",IFERROR(VLOOKUP($A13,Artikelstamm!$B:$I,2,FALSE),"")) | C13: =IF($A13="","",IFERROR(VLOOKUP($A13,Artikelstamm!$B:$I,3,FALSE),"")) | D13: =IF($A13="","",IFERROR(VLOOKUP($A13,Artikelstamm!$B:$I,4,FALSE),"")) | E13: =IF($A13="","",IFERROR(VLOOKUP($A13,Artikelstamm!$B:$I,6,FALSE),"")) | G13: =IF($A13="","",IF(COUNTIF(Artikelstamm!$B:$B,$A13)=0,"NEU – in Artikelstamm aufnehmen","OK"))
B14: =IF($A14="","",IFERROR(VLOOKUP($A14,Artikelstamm!$B:$I,2,FALSE),"")) | C14: =IF($A14="","",IFERROR(VLOOKUP($A14,Artikelstamm!$B:$I,3,FALSE),"")) | D14: =IF($A14="","",IFERROR(VLOOKUP($A14,Artikelstamm!$B:$I,4,FALSE),"")) | E14: =IF($A14="","",IFERROR(VLOOKUP($A14,Artikelstamm!$B:$I,6,FALSE),"")) | G14: =IF($A14="","",IF(COUNTIF(Artikelstamm!$B:$B,$A14)=0,"NEU – in Artikelstamm aufnehmen","OK"))
B15: =IF($A15="","",IFERROR(VLOOKUP($A15,Artikelstamm!$B:$I,2,FALSE),"")) | C15: =IF($A15="","",IFERROR(VLOOKUP($A15,Artikelstamm!$B:$I,3,FALSE),"")) | D15: =IF($A15="","",IFERROR(VLOOKUP($A15,Artikelstamm!$B:$I,4,FALSE),"")) | E15: =IF($A15="","",IFERROR(VLOOKUP($A15,Artikelstamm!$B:$I,6,FALSE),"")) | G15: =IF($A15="","",IF(COUNTIF(Artikelstamm!$B:$B,$A15)=0,"NEU – in Artikelstamm aufnehmen","OK"))
B16: =IF($A16="","",IFERROR(VLOOKUP($A16,Artikelstamm!$B:$I,2,FALSE),"")) | C16: =IF($A16="","",IFERROR(VLOOKUP($A16,Artikelstamm!$B:$I,3,FALSE),"")) | D16: =IF($A16="","",IFERROR(VLOOKUP($A16,Artikelstamm!$B:$I,4,FALSE),"")) | E16: =IF($A16="","",IFERROR(VLOOKUP($A16,Artikelstamm!$B:$I,6,FALSE),"")) | G16: =IF($A16="","",IF(COUNTIF(Artikelstamm!$B:$B,$A16)=0,"NEU – in Artikelstamm aufnehmen","OK"))
B17: =IF($A17="","",IFERROR(VLOOKUP($A17,Artikelstamm!$B:$I,2,FALSE),"")) | C17: =IF($A17="","",IFERROR(VLOOKUP($A17,Artikelstamm!$B:$I,3,FALSE),"")) | D17: =IF($A17="","",IFERROR(VLOOKUP($A17,Artikelstamm!$B:$I,4,FALSE),"")) | E17: =IF($A17="","",IFERROR(VLOOKUP($A17,Artikelstamm!$B:$I,6,FALSE),"")) | G17: =IF($A17="","",IF(COUNTIF(Artikelstamm!$B:$B,$A17)=0,"NEU – in Artikelstamm aufnehmen","OK"))
B18: =IF($A18="","",IFERROR(VLOOKUP($A18,Artikelstamm!$B:$I,2,FALSE),"")) | C18: =IF($A18="","",IFERROR(VLOOKUP($A18,Artikelstamm!$B:$I,3,FALSE),"")) | D18: =IF($A18="","",IFERROR(VLOOKUP($A18,Artikelstamm!$B:$I,4,FALSE),"")) | E18: =IF($A18="","",IFERROR(VLOOKUP($A18,Artikelstamm!$B:$I,6,FALSE),"")) | G18: =IF($A18="","",IF(COUNTIF(Artikelstamm!$B:$B,$A18)=0,"NEU – in Artikelstamm aufnehmen","OK"))
B19: =IF($A19="","",IFERROR(VLOOKUP($A19,Artikelstamm!$B:$I,2,FALSE),"")) | C19: =IF($A19="","",IFERROR(VLOOKUP($A19,Artikelstamm!$B:$I,3,FALSE),"")) | D19: =IF($A19="","",IFERROR(VLOOKUP($A19,Artikelstamm!$B:$I,4,FALSE),"")) | E19: =IF($A19="","",IFERROR(VLOOKUP($A19,Artikelstamm!$B:$I,6,FALSE),"")) | G19: =IF($A19="","",IF(COUNTIF(Artikelstamm!$B:$B,$A19)=0,"NEU – in Artikelstamm aufnehmen","OK"))
B20: =IF($A20="","",IFERROR(VLOOKUP($A20,Artikelstamm!$B:$I,2,FALSE),"")) | C20: =IF($A20="","",IFERROR(VLOOKUP($A20,Artikelstamm!$B:$I,3,FALSE),"")) | D20: =IF($A20="","",IFERROR(VLOOKUP($A20,Artikelstamm!$B:$I,4,FALSE),"")) | E20: =IF($A20="","",IFERROR(VLOOKUP($A20,Artikelstamm!$B:$I,6,FALSE),"")) | G20: =IF($A20="","",IF(COUNTIF(Artikelstamm!$B:$B,$A20)=0,"NEU – in Artikelstamm aufnehmen","OK"))
... B258: =IF($A258="","",IFERROR(VLOOKUP($A258,Artikelstamm!$B:$I,2,FALSE),"")) | C258: =IF($A258="","",IFERROR(VLOOKUP($A258,Artikelstamm!$B:$I,3,FALSE),"")) | D258: =IF($A258="","",IFERROR(VLOOKUP($A258,Artikelstamm!$B:$I,4,FALSE),"")) | E258: =IF($A258="","",IFERROR(VLOOKUP($A258,Artikelstamm!$B:$I,6,FALSE),"")) | G258: =IF($A258="","",IF(COUNTIF(Artikelstamm!$B:$B,$A258)=0,"NEU – in Artikelstamm aufnehmen","OK"))

Sheet Bar
A1: Inventurliste – Bar
A2: Vier Jahreszeiten Schluchsee
A4: Standort: | B4: Bar
A5: Datum: | B5: 30.09.2026
A6: Aufgenommen von:
A7: Nur die Spalten „Artikel“ und „Bestand (gezählt)“ ausfüllen – in „Artikel“ einfach lostippen (z. B. „Coca“) und aus der Liste wählen. Alles andere kommt automatisch, lässt sich aber überschreiben.
A8: Artikel | B8: Warengruppe | C8: Gebinde / Größe | D8: Einheit | E8: Lieferant | F8: Bestand (gezählt) | G8: Status | H8: Bemerkung
B9: =IF($A9="","",IFERROR(VLOOKUP($A9,Artikelstamm!$B:$I,2,FALSE),"")) | C9: =IF($A9="","",IFERROR(VLOOKUP($A9,Artikelstamm!$B:$I,3,FALSE),"")) | D9: =IF($A9="","",IFERROR(VLOOKUP($A9,Artikelstamm!$B:$I,4,FALSE),"")) | E9: =IF($A9="","",IFERROR(VLOOKUP($A9,Artikelstamm!$B:$I,6,FALSE),"")) | G9: =IF($A9="","",IF(COUNTIF(Artikelstamm!$B:$B,$A9)=0,"NEU – in Artikelstamm aufnehmen","OK"))
B10: =IF($A10="","",IFERROR(VLOOKUP($A10,Artikelstamm!$B:$I,2,FALSE),"")) | C10: =IF($A10="","",IFERROR(VLOOKUP($A10,Artikelstamm!$B:$I,3,FALSE),"")) | D10: =IF($A10="","",IFERROR(VLOOKUP($A10,Artikelstamm!$B:$I,4,FALSE),"")) | E10: =IF($A10="","",IFERROR(VLOOKUP($A10,Artikelstamm!$B:$I,6,FALSE),"")) | G10: =IF($A10="","",IF(COUNTIF(Artikelstamm!$B:$B,$A10)=0,"NEU – in Artikelstamm aufnehmen","OK"))
B11: =IF($A11="","",IFERROR(VLOOKUP($A11,Artikelstamm!$B:$I,2,FALSE),"")) | C11: =IF($A11="","",IFERROR(VLOOKUP($A11,Artikelstamm!$B:$I,3,FALSE),"")) | D11: =IF($A11="","",IFERROR(VLOOKUP($A11,Artikelstamm!$B:$I,4,FALSE),"")) | E11: =IF($A11="","",IFERROR(VLOOKUP($A11,Artikelstamm!$B:$I,6,FALSE),"")) | G11: =IF($A11="","",IF(COUNTIF(Artikelstamm!$B:$B,$A11)=0,"NEU – in Artikelstamm aufnehmen","OK"))
B12: =IF($A12="","",IFERROR(VLOOKUP($A12,Artikelstamm!$B:$I,2,FALSE),"")) | C12: =IF($A12="","",IFERROR(VLOOKUP($A12,Artikelstamm!$B:$I,3,FALSE),"")) | D12: =IF($A12="","",IFERROR(VLOOKUP($A12,Artikelstamm!$B:$I,4,FALSE),"")) | E12: =IF($A12="","",IFERROR(VLOOKUP($A12,Artikelstamm!$B:$I,6,FALSE),"")) | G12: =IF($A12="","",IF(COUNTIF(Artikelstamm!$B:$B,$A12)=0,"NEU – in Artikelstamm aufnehmen","OK"))
B13: =IF($A13="","",IFERROR(VLOOKUP($A13,Artikelstamm!$B:$I,2,FALSE),"")) | C13: =IF($A13="","",IFERROR(VLOOKUP($A13,Artikelstamm!$B:$I,3,FALSE),"")) | D13: =IF($A13="","",IFERROR(VLOOKUP($A13,Artikelstamm!$B:$I,4,FALSE),"")) | E13: =IF($A13="","",IFERROR(VLOOKUP($A13,Artikelstamm!$B:$I,6,FALSE),"")) | G13: =IF($A13="","",IF(COUNTIF(Artikelstamm!$B:$B,$A13)=0,"NEU – in Artikelstamm aufnehmen","OK"))
B14: =IF($A14="","",IFERROR(VLOOKUP($A14,Artikelstamm!$B:$I,2,FALSE),"")) | C14: =IF($A14="","",IFERROR(VLOOKUP($A14,Artikelstamm!$B:$I,3,FALSE),"")) | D14: =IF($A14="","",IFERROR(VLOOKUP($A14,Artikelstamm!$B:$I,4,FALSE),"")) | E14: =IF($A14="","",IFERROR(VLOOKUP($A14,Artikelstamm!$B:$I,6,FALSE),"")) | G14: =IF($A14="","",IF(COUNTIF(Artikelstamm!$B:$B,$A14)=0,"NEU – in Artikelstamm aufnehmen","OK"))
B15: =IF($A15="","",IFERROR(VLOOKUP($A15,Artikelstamm!$B:$I,2,FALSE),"")) | C15: =IF($A15="","",IFERROR(VLOOKUP($A15,Artikelstamm!$B:$I,3,FALSE),"")) | D15: =IF($A15="","",IFERROR(VLOOKUP($A15,Artikelstamm!$B:$I,4,FALSE),"")) | E15: =IF($A15="","",IFERROR(VLOOKUP($A15,Artikelstamm!$B:$I,6,FALSE),"")) | G15: =IF($A15="","",IF(COUNTIF(Artikelstamm!$B:$B,$A15)=0,"NEU – in Artikelstamm aufnehmen","OK"))
B16: =IF($A16="","",IFERROR(VLOOKUP($A16,Artikelstamm!$B:$I,2,FALSE),"")) | C16: =IF($A16="","",IFERROR(VLOOKUP($A16,Artikelstamm!$B:$I,3,FALSE),"")) | D16: =IF($A16="","",IFERROR(VLOOKUP($A16,Artikelstamm!$B:$I,4,FALSE),"")) | E16: =IF($A16="","",IFERROR(VLOOKUP($A16,Artikelstamm!$B:$I,6,FALSE),"")) | G16: =IF($A16="","",IF(COUNTIF(Artikelstamm!$B:$B,$A16)=0,"NEU – in Artikelstamm aufnehmen","OK"))
B17: =IF($A17="","",IFERROR(VLOOKUP($A17,Artikelstamm!$B:$I,2,FALSE),"")) | C17: =IF($A17="","",IFERROR(VLOOKUP($A17,Artikelstamm!$B:$I,3,FALSE),"")) | D17: =IF($A17="","",IFERROR(VLOOKUP($A17,Artikelstamm!$B:$I,4,FALSE),"")) | E17: =IF($A17="","",IFERROR(VLOOKUP($A17,Artikelstamm!$B:$I,6,FALSE),"")) | G17: =IF($A17="","",IF(COUNTIF(Artikelstamm!$B:$B,$A17)=0,"NEU – in Artikelstamm aufnehmen","OK"))
B18: =IF($A18="","",IFERROR(VLOOKUP($A18,Artikelstamm!$B:$I,2,FALSE),"")) | C18: =IF($A18="","",IFERROR(VLOOKUP($A18,Artikelstamm!$B:$I,3,FALSE),"")) | D18: =IF($A18="","",IFERROR(VLOOKUP($A18,Artikelstamm!$B:$I,4,FALSE),"")) | E18: =IF($A18="","",IFERROR(VLOOKUP($A18,Artikelstamm!$B:$I,6,FALSE),"")) | G18: =IF($A18="","",IF(COUNTIF(Artikelstamm!$B:$B,$A18)=0,"NEU – in Artikelstamm aufnehmen","OK"))
B19: =IF($A19="","",IFERROR(VLOOKUP($A19,Artikelstamm!$B:$I,2,FALSE),"")) | C19: =IF($A19="","",IFERROR(VLOOKUP($A19,Artikelstamm!$B:$I,3,FALSE),"")) | D19: =IF($A19="","",IFERROR(VLOOKUP($A19,Artikelstamm!$B:$I,4,FALSE),"")) | E19: =IF($A19="","",IFERROR(VLOOKUP($A19,Artikelstamm!$B:$I,6,FALSE),"")) | G19: =IF($A19="","",IF(COUNTIF(Artikelstamm!$B:$B,$A19)=0,"NEU – in Artikelstamm aufnehmen","OK"))
B20: =IF($A20="","",IFERROR(VLOOKUP($A20,Artikelstamm!$B:$I,2,FALSE),"")) | C20: =IF($A20="","",IFERROR(VLOOKUP($A20,Artikelstamm!$B:$I,3,FALSE),"")) | D20: =IF($A20="","",IFERROR(VLOOKUP($A20,Artikelstamm!$B:$I,4,FALSE),"")) | E20: =IF($A20="","",IFERROR(VLOOKUP($A20,Artikelstamm!$B:$I,6,FALSE),"")) | G20: =IF($A20="","",IF(COUNTIF(Artikelstamm!$B:$B,$A20)=0,"NEU – in Artikelstamm aufnehmen","OK"))
... B258: =IF($A258="","",IFERROR(VLOOKUP($A258,Artikelstamm!$B:$I,2,FALSE),"")) | C258: =IF($A258="","",IFERROR(VLOOKUP($A258,Artikelstamm!$B:$I,3,FALSE),"")) | D258: =IF($A258="","",IFERROR(VLOOKUP($A258,Artikelstamm!$B:$I,4,FALSE),"")) | E258: =IF($A258="","",IFERROR(VLOOKUP($A258,Artikelstamm!$B:$I,6,FALSE),"")) | G258: =IF($A258="","",IF(COUNTIF(Artikelstamm!$B:$B,$A258)=0,"NEU – in Artikelstamm aufnehmen","OK"))

Sheet Suche
A1: Artikel suchen
A2: Vier Jahreszeiten Schluchsee
A4: Suchbegriff:
A5: Treffer: | B5: =SUM(Artikelstamm!$K$5:$K$500)
A6: Stichwort oben eintippen – z. B. „cola“, „burgunder“, „wasser“, „rothaus“, „reiniger“. Gesucht wird an beliebiger Stelle in Artikelname, Warengruppe und Lieferant; Groß- und Kleinschreibung spielt keine Rolle. Leeres Feld = alle Artikel. Es werden die ersten 40 Treffer angezeigt.
A7: Artikel | B7: Gebinde / Größe | C7: Einheit | D7: Inhalt je Gebinde | E7: Lieferant | F7: Warengruppe | G7: Lagerort | H7: Art.-Nr.
A8: =IFERROR(INDEX(Artikelstamm!$B:$B,$J8),"") | B8: =IFERROR(INDEX(Artikelstamm!$D:$D,$J8),"") | C8: =IFERROR(INDEX(Artikelstamm!$E:$E,$J8),"") | D8: =IFERROR(INDEX(Artikelstamm!$F:$F,$J8),"") | E8: =IFERROR(INDEX(Artikelstamm!$G:$G,$J8),"") | F8: =IFERROR(INDEX(Artikelstamm!$C:$C,$J8),"") | G8: =IFERROR(INDEX(Artikelstamm!$H:$H,$J8),"") | H8: =IFERROR(INDEX(Artikelstamm!$A:$A,$J8),"") | J8: =IFERROR(MATCH(ROW()-7,Artikelstamm!$L$5:$L$500,0)+4,"")
A9: =IFERROR(INDEX(Artikelstamm!$B:$B,$J9),"") | B9: =IFERROR(INDEX(Artikelstamm!$D:$D,$J9),"") | C9: =IFERROR(INDEX(Artikelstamm!$E:$E,$J9),"") | D9: =IFERROR(INDEX(Artikelstamm!$F:$F,$J9),"") | E9: =IFERROR(INDEX(Artikelstamm!$G:$G,$J9),"") | F9: =IFERROR(INDEX(Artikelstamm!$C:$C,$J9),"") | G9: =IFERROR(INDEX(Artikelstamm!$H:$H,$J9),"") | H9: =IFERROR(INDEX(Artikelstamm!$A:$A,$J9),"") | J9: =IFERROR(MATCH(ROW()-7,Artikelstamm!$L$5:$L$500,0)+4,"")
A10: =IFERROR(INDEX(Artikelstamm!$B:$B,$J10),"") | B10: =IFERROR(INDEX(Artikelstamm!$D:$D,$J10),"") | C10: =IFERROR(INDEX(Artikelstamm!$E:$E,$J10),"") | D10: =IFERROR(INDEX(Artikelstamm!$F:$F,$J10),"") | E10: =IFERROR(INDEX(Artikelstamm!$G:$G,$J10),"") | F10: =IFERROR(INDEX(Artikelstamm!$C:$C,$J10),"") | G10: =IFERROR(INDEX(Artikelstamm!$H:$H,$J10),"") | H10: =IFERROR(INDEX(Artikelstamm!$A:$A,$J10),"") | J10: =IFERROR(MATCH(ROW()-7,Artikelstamm!$L$5:$L$500,0)+4,"")
A11: =IFERROR(INDEX(Artikelstamm!$B:$B,$J11),"") | B11: =IFERROR(INDEX(Artikelstamm!$D:$D,$J11),"") | C11: =IFERROR(INDEX(Artikelstamm!$E:$E,$J11),"") | D11: =IFERROR(INDEX(Artikelstamm!$F:$F,$J11),"") | E11: =IFERROR(INDEX(Artikelstamm!$G:$G,$J11),"") | F11: =IFERROR(INDEX(Artikelstamm!$C:$C,$J11),"") | G11: =IFERROR(INDEX(Artikelstamm!$H:$H,$J11),"") | H11: =IFERROR(INDEX(Artikelstamm!$A:$A,$J11),"") | J11: =IFERROR(MATCH(ROW()-7,Artikelstamm!$L$5:$L$500,0)+4,"")
A12: =IFERROR(INDEX(Artikelstamm!$B:$B,$J12),"") | B12: =IFERROR(INDEX(Artikelstamm!$D:$D,$J12),"") | C12: =IFERROR(INDEX(Artikelstamm!$E:$E,$J12),"") | D12: =IFERROR(INDEX(Artikelstamm!$F:$F,$J12),"") | E12: =IFERROR(INDEX(Artikelstamm!$G:$G,$J12),"") | F12: =IFERROR(INDEX(Artikelstamm!$C:$C,$J12),"") | G12: =IFERROR(INDEX(Artikelstamm!$H:$H,$J12),"") | H12: =IFERROR(INDEX(Artikelstamm!$A:$A,$J12),"") | J12: =IFERROR(MATCH(ROW()-7,Artikelstamm!$L$5:$L$500,0)+4,"")
A13: =IFERROR(INDEX(Artikelstamm!$B:$B,$J13),"") | B13: =IFERROR(INDEX(Artikelstamm!$D:$D,$J13),"") | C13: =IFERROR(INDEX(Artikelstamm!$E:$E,$J13),"") | D13: =IFERROR(INDEX(Artikelstamm!$F:$F,$J13),"") | E13: =IFERROR(INDEX(Artikelstamm!$G:$G,$J13),"") | F13: =IFERROR(INDEX(Artikelstamm!$C:$C,$J13),"") | G13: =IFERROR(INDEX(Artikelstamm!$H:$H,$J13),"") | H13: =IFERROR(INDEX(Artikelstamm!$A:$A,$J13),"") | J13: =IFERROR(MATCH(ROW()-7,Artikelstamm!$L$5:$L$500,0)+4,"")
A14: =IFERROR(INDEX(Artikelstamm!$B:$B,$J14),"") | B14: =IFERROR(INDEX(Artikelstamm!$D:$D,$J14),"") | C14: =IFERROR(INDEX(Artikelstamm!$E:$E,$J14),"") | D14: =IFERROR(INDEX(Artikelstamm!$F:$F,$J14),"") | E14: =IFERROR(INDEX(Artikelstamm!$G:$G,$J14),"") | F14: =IFERROR(INDEX(Artikelstamm!$C:$C,$J14),"") | G14: =IFERROR(INDEX(Artikelstamm!$H:$H,$J14),"") | H14: =IFERROR(INDEX(Artikelstamm!$A:$A,$J14),"") | J14: =IFERROR(MATCH(ROW()-7,Artikelstamm!$L$5:$L$500,0)+4,"")
A15: =IFERROR(INDEX(Artikelstamm!$B:$B,$J15),"") | B15: =IFERROR(INDEX(Artikelstamm!$D:$D,$J15),"") | C15: =IFERROR(INDEX(Artikelstamm!$E:$E,$J15),"") | D15: =IFERROR(INDEX(Artikelstamm!$F:$F,$J15),"") | E15: =IFERROR(INDEX(Artikelstamm!$G:$G,$J15),"") | F15: =IFERROR(INDEX(Artikelstamm!$C:$C,$J15),"") | G15: =IFERROR(INDEX(Artikelstamm!$H:$H,$J15),"") | H15: =IFERROR(INDEX(Artikelstamm!$A:$A,$J15),"") | J15: =IFERROR(MATCH(ROW()-7,Artikelstamm!$L$5:$L$500,0)+4,"")
A16: =IFERROR(INDEX(Artikelstamm!$B:$B,$J16),"") | B16: =IFERROR(INDEX(Artikelstamm!$D:$D,$J16),"") | C16: =IFERROR(INDEX(Artikelstamm!$E:$E,$J16),"") | D16: =IFERROR(INDEX(Artikelstamm!$F:$F,$J16),"") | E16: =IFERROR(INDEX(Artikelstamm!$G:$G,$J16),"") | F16: =IFERROR(INDEX(Artikelstamm!$C:$C,$J16),"") | G16: =IFERROR(INDEX(Artikelstamm!$H:$H,$J16),"") | H16: =IFERROR(INDEX(Artikelstamm!$A:$A,$J16),"") | J16: =IFERROR(MATCH(ROW()-7,Artikelstamm!$L$5:$L$500,0)+4,"")
A17: =IFERROR(INDEX(Artikelstamm!$B:$B,$J17),"") | B17: =IFERROR(INDEX(Artikelstamm!$D:$D,$J17),"") | C17: =IFERROR(INDEX(Artikelstamm!$E:$E,$J17),"") | D17: =IFERROR(INDEX(Artikelstamm!$F:$F,$J17),"") | E17: =IFERROR(INDEX(Artikelstamm!$G:$G,$J17),"") | F17: =IFERROR(INDEX(Artikelstamm!$C:$C,$J17),"") | G17: =IFERROR(INDEX(Artikelstamm!$H:$H,$J17),"") | H17: =IFERROR(INDEX(Artikelstamm!$A:$A,$J17),"") | J17: =IFERROR(MATCH(ROW()-7,Artikelstamm!$L$5:$L$500,0)+4,"")
A18: =IFERROR(INDEX(Artikelstamm!$B:$B,$J18),"") | B18: =IFERROR(INDEX(Artikelstamm!$D:$D,$J18),"") | C18: =IFERROR(INDEX(Artikelstamm!$E:$E,$J18),"") | D18: =IFERROR(INDEX(Artikelstamm!$F:$F,$J18),"") | E18: =IFERROR(INDEX(Artikelstamm!$G:$G,$J18),"") | F18: =IFERROR(INDEX(Artikelstamm!$C:$C,$J18),"") | G18: =IFERROR(INDEX(Artikelstamm!$H:$H,$J18),"") | H18: =IFERROR(INDEX(Artikelstamm!$A:$A,$J18),"") | J18: =IFERROR(MATCH(ROW()-7,Artikelstamm!$L$5:$L$500,0)+4,"")
A19: =IFERROR(INDEX(Artikelstamm!$B:$B,$J19),"") | B19: =IFERROR(INDEX(Artikelstamm!$D:$D,$J19),"") | C19: =IFERROR(INDEX(Artikelstamm!$E:$E,$J19),"") | D19: =IFERROR(INDEX(Artikelstamm!$F:$F,$J19),"") | E19: =IFERROR(INDEX(Artikelstamm!$G:$G,$J19),"") | F19: =IFERROR(INDEX(Artikelstamm!$C:$C,$J19),"") | G19: =IFERROR(INDEX(Artikelstamm!$H:$H,$J19),"") | H19: =IFERROR(INDEX(Artikelstamm!$A:$A,$J19),"") | J19: =IFERROR(MATCH(ROW()-7,Artikelstamm!$L$5:$L$500,0)+4,"")
... A47: =IFERROR(INDEX(Artikelstamm!$B:$B,$J47),"") | B47: =IFERROR(INDEX(Artikelstamm!$D:$D,$J47),"") | C47: =IFERROR(INDEX(Artikelstamm!$E:$E,$J47),"") | D47: =IFERROR(INDEX(Artikelstamm!$F:$F,$J47),"") | E47: =IFERROR(INDEX(Artikelstamm!$G:$G,$J47),"") | F47: =IFERROR(INDEX(Artikelstamm!$C:$C,$J47),"") | G47: =IFERROR(INDEX(Artikelstamm!$H:$H,$J47),"") | H47: =IFERROR(INDEX(Artikelstamm!$A:$A,$J47),"") | J47: =IFERROR(MATCH(ROW()-7,Artikelstamm!$L$5:$L$500,0)+4,"")

Sheet Neue Artikel
A1: Neue Artikel – Aufnahme in den Artikelstamm
A2: Vier Jahreszeiten Schluchsee
A3: Alles, was beim Zählen als „NEU“ markiert war, hier vollständig erfassen. Danach die Spalten B bis J markieren, kopieren und im Blatt „Artikelstamm“ unten anfügen – ab dann steht der Artikel überall zur Auswahl.
A4: Gefunden in | B4: Art.-Nr. | C4: Artikel | D4: Warengruppe | E4: Gebinde / Größe | F4: Einheit | G4: Inhalt je Gebinde | H4: Lieferant | I4: Lagerort | J4: Bemerkung

Sheet Auswertung
A1: Auswertung – Gesamtbestand je Artikel
A2: Vier Jahreszeiten Schluchsee
A3: Summiert automatisch über alle sechs Zählblätter. Hier nichts eintragen.
A4: Art.-Nr. | B4: Artikel | C4: Warengruppe | D4: Einheit | E4: Hauptmagazin | F4: Panorama | G4: Kachelofen | H4: Gugelhupf | I4: Lucia | J4: Bar | K4: Gesamt
A5: =IF(Artikelstamm!$A5="","",Artikelstamm!$A5) | B5: =IF(Artikelstamm!$B5="","",Artikelstamm!$B5) | C5: =IF(Artikelstamm!$C5="","",Artikelstamm!$C5) | D5: =IF(Artikelstamm!$E5="","",Artikelstamm!$E5) | E5: =SUMIF('Hauptmagazin'!$A:$A,$B5,'Hauptmagazin'!$F:$F) | F5: =SUMIF('Panorama'!$A:$A,$B5,'Panorama'!$F:$F) | G5: =SUMIF('Kachelofen'!$A:$A,$B5,'Kachelofen'!$F:$F) | H5: =SUMIF('Gugelhupf'!$A:$A,$B5,'Gugelhupf'!$F:$F) | I5: =SUMIF('Lucia'!$A:$A,$B5,'Lucia'!$F:$F) | J5: =SUMIF('Bar'!$A:$A,$B5,'Bar'!$F:$F) | K5: =SUM(E5:J5)
A6: =IF(Artikelstamm!$A6="","",Artikelstamm!$A6) | B6: =IF(Artikelstamm!$B6="","",Artikelstamm!$B6) | C6: =IF(Artikelstamm!$C6="","",Artikelstamm!$C6) | D6: =IF(Artikelstamm!$E6="","",Artikelstamm!$E6) | E6: =SUMIF('Hauptmagazin'!$A:$A,$B6,'Hauptmagazin'!$F:$F) | F6: =SUMIF('Panorama'!$A:$A,$B6,'Panorama'!$F:$F) | G6: =SUMIF('Kachelofen'!$A:$A,$B6,'Kachelofen'!$F:$F) | H6: =SUMIF('Gugelhupf'!$A:$A,$B6,'Gugelhupf'!$F:$F) | I6: =SUMIF('Lucia'!$A:$A,$B6,'Lucia'!$F:$F) | J6: =SUMIF('Bar'!$A:$A,$B6,'Bar'!$F:$F) | K6: =SUM(E6:J6)
A7: =IF(Artikelstamm!$A7="","",Artikelstamm!$A7) | B7: =IF(Artikelstamm!$B7="","",Artikelstamm!$B7) | C7: =IF(Artikelstamm!$C7="","",Artikelstamm!$C7) | D7: =IF(Artikelstamm!$E7="","",Artikelstamm!$E7) | E7: =SUMIF('Hauptmagazin'!$A:$A,$B7,'Hauptmagazin'!$F:$F) | F7: =SUMIF('Panorama'!$A:$A,$B7,'Panorama'!$F:$F) | G7: =SUMIF('Kachelofen'!$A:$A,$B7,'Kachelofen'!$F:$F) | H7: =SUMIF('Gugelhupf'!$A:$A,$B7,'Gugelhupf'!$F:$F) | I7: =SUMIF('Lucia'!$A:$A,$B7,'Lucia'!$F:$F) | J7: =SUMIF('Bar'!$A:$A,$B7,'Bar'!$F:$F) | K7: =SUM(E7:J7)
A8: =IF(Artikelstamm!$A8="","",Artikelstamm!$A8) | B8: =IF(Artikelstamm!$B8="","",Artikelstamm!$B8) | C8: =IF(Artikelstamm!$C8="","",Artikelstamm!$C8) | D8: =IF(Artikelstamm!$E8="","",Artikelstamm!$E8) | E8: =SUMIF('Hauptmagazin'!$A:$A,$B8,'Hauptmagazin'!$F:$F) | F8: =SUMIF('Panorama'!$A:$A,$B8,'Panorama'!$F:$F) | G8: =SUMIF('Kachelofen'!$A:$A,$B8,'Kachelofen'!$F:$F) | H8: =SUMIF('Gugelhupf'!$A:$A,$B8,'Gugelhupf'!$F:$F) | I8: =SUMIF('Lucia'!$A:$A,$B8,'Lucia'!$F:$F) | J8: =SUMIF('Bar'!$A:$A,$B8,'Bar'!$F:$F) | K8: =SUM(E8:J8)
A9: =IF(Artikelstamm!$A9="","",Artikelstamm!$A9) | B9: =IF(Artikelstamm!$B9="","",Artikelstamm!$B9) | C9: =IF(Artikelstamm!$C9="","",Artikelstamm!$C9) | D9: =IF(Artikelstamm!$E9="","",Artikelstamm!$E9) | E9: =SUMIF('Hauptmagazin'!$A:$A,$B9,'Hauptmagazin'!$F:$F) | F9: =SUMIF('Panorama'!$A:$A,$B9,'Panorama'!$F:$F) | G9: =SUMIF('Kachelofen'!$A:$A,$B9,'Kachelofen'!$F:$F) | H9: =SUMIF('Gugelhupf'!$A:$A,$B9,'Gugelhupf'!$F:$F) | I9: =SUMIF('Lucia'!$A:$A,$B9,'Lucia'!$F:$F) | J9: =SUMIF('Bar'!$A:$A,$B9,'Bar'!$F:$F) | K9: =SUM(E9:J9)
A10: =IF(Artikelstamm!$A10="","",Artikelstamm!$A10) | B10: =IF(Artikelstamm!$B10="","",Artikelstamm!$B10) | C10: =IF(Artikelstamm!$C10="","",Artikelstamm!$C10) | D10: =IF(Artikelstamm!$E10="","",Artikelstamm!$E10) | E10: =SUMIF('Hauptmagazin'!$A:$A,$B10,'Hauptmagazin'!$F:$F) | F10: =SUMIF('Panorama'!$A:$A,$B10,'Panorama'!$F:$F) | G10: =SUMIF('Kachelofen'!$A:$A,$B10,'Kachelofen'!$F:$F) | H10: =SUMIF('Gugelhupf'!$A:$A,$B10,'Gugelhupf'!$F:$F) | I10: =SUMIF('Lucia'!$A:$A,$B10,'Lucia'!$F:$F) | J10: =SUMIF('Bar'!$A:$A,$B10,'Bar'!$F:$F) | K10: =SUM(E10:J10)
A11: =IF(Artikelstamm!$A11="","",Artikelstamm!$A11) | B11: =IF(Artikelstamm!$B11="","",Artikelstamm!$B11) | C11: =IF(Artikelstamm!$C11="","",Artikelstamm!$C11) | D11: =IF(Artikelstamm!$E11="","",Artikelstamm!$E11) | E11: =SUMIF('Hauptmagazin'!$A:$A,$B11,'Hauptmagazin'!$F:$F) | F11: =SUMIF('Panorama'!$A:$A,$B11,'Panorama'!$F:$F) | G11: =SUMIF('Kachelofen'!$A:$A,$B11,'Kachelofen'!$F:$F) | H11: =SUMIF('Gugelhupf'!$A:$A,$B11,'Gugelhupf'!$F:$F) | I11: =SUMIF('Lucia'!$A:$A,$B11,'Lucia'!$F:$F) | J11: =SUMIF('Bar'!$A:$A,$B11,'Bar'!$F:$F) | K11: =SUM(E11:J11)
A12: =IF(Artikelstamm!$A12="","",Artikelstamm!$A12) | B12: =IF(Artikelstamm!$B12="","",Artikelstamm!$B12) | C12: =IF(Artikelstamm!$C12="","",Artikelstamm!$C12) | D12: =IF(Artikelstamm!$E12="","",Artikelstamm!$E12) | E12: =SUMIF('Hauptmagazin'!$A:$A,$B12,'Hauptmagazin'!$F:$F) | F12: =SUMIF('Panorama'!$A:$A,$B12,'Panorama'!$F:$F) | G12: =SUMIF('Kachelofen'!$A:$A,$B12,'Kachelofen'!$F:$F) | H12: =SUMIF('Gugelhupf'!$A:$A,$B12,'Gugelhupf'!$F:$F) | I12: =SUMIF('Lucia'!$A:$A,$B12,'Lucia'!$F:$F) | J12: =SUMIF('Bar'!$A:$A,$B12,'Bar'!$F:$F) | K12: =SUM(E12:J12)
A13: =IF(Artikelstamm!$A13="","",Artikelstamm!$A13) | B13: =IF(Artikelstamm!$B13="","",Artikelstamm!$B13) | C13: =IF(Artikelstamm!$C13="","",Artikelstamm!$C13) | D13: =IF(Artikelstamm!$E13="","",Artikelstamm!$E13) | E13: =SUMIF('Hauptmagazin'!$A:$A,$B13,'Hauptmagazin'!$F:$F) | F13: =SUMIF('Panorama'!$A:$A,$B13,'Panorama'!$F:$F) | G13: =SUMIF('Kachelofen'!$A:$A,$B13,'Kachelofen'!$F:$F) | H13: =SUMIF('Gugelhupf'!$A:$A,$B13,'Gugelhupf'!$F:$F) | I13: =SUMIF('Lucia'!$A:$A,$B13,'Lucia'!$F:$F) | J13: =SUMIF('Bar'!$A:$A,$B13,'Bar'!$F:$F) | K13: =SUM(E13:J13)
A14: =IF(Artikelstamm!$A14="","",Artikelstamm!$A14) | B14: =IF(Artikelstamm!$B14="","",Artikelstamm!$B14) | C14: =IF(Artikelstamm!$C14="","",Artikelstamm!$C14) | D14: =IF(Artikelstamm!$E14="","",Artikelstamm!$E14) | E14: =SUMIF('Hauptmagazin'!$A:$A,$B14,'Hauptmagazin'!$F:$F) | F14: =SUMIF('Panorama'!$A:$A,$B14,'Panorama'!$F:$F) | G14: =SUMIF('Kachelofen'!$A:$A,$B14,'Kachelofen'!$F:$F) | H14: =SUMIF('Gugelhupf'!$A:$A,$B14,'Gugelhupf'!$F:$F) | I14: =SUMIF('Lucia'!$A:$A,$B14,'Lucia'!$F:$F) | J14: =SUMIF('Bar'!$A:$A,$B14,'Bar'!$F:$F) | K14: =SUM(E14:J14)
A15: =IF(Artikelstamm!$A15="","",Artikelstamm!$A15) | B15: =IF(Artikelstamm!$B15="","",Artikelstamm!$B15) | C15: =IF(Artikelstamm!$C15="","",Artikelstamm!$C15) | D15: =IF(Artikelstamm!$E15="","",Artikelstamm!$E15) | E15: =SUMIF('Hauptmagazin'!$A:$A,$B15,'Hauptmagazin'!$F:$F) | F15: =SUMIF('Panorama'!$A:$A,$B15,'Panorama'!$F:$F) | G15: =SUMIF('Kachelofen'!$A:$A,$B15,'Kachelofen'!$F:$F) | H15: =SUMIF('Gugelhupf'!$A:$A,$B15,'Gugelhupf'!$F:$F) | I15: =SUMIF('Lucia'!$A:$A,$B15,'Lucia'!$F:$F) | J15: =SUMIF('Bar'!$A:$A,$B15,'Bar'!$F:$F) | K15: =SUM(E15:J15)
A16: =IF(Artikelstamm!$A16="","",Artikelstamm!$A16) | B16: =IF(Artikelstamm!$B16="","",Artikelstamm!$B16) | C16: =IF(Artikelstamm!$C16="","",Artikelstamm!$C16) | D16: =IF(Artikelstamm!$E16="","",Artikelstamm!$E16) | E16: =SUMIF('Hauptmagazin'!$A:$A,$B16,'Hauptmagazin'!$F:$F) | F16: =SUMIF('Panorama'!$A:$A,$B16,'Panorama'!$F:$F) | G16: =SUMIF('Kachelofen'!$A:$A,$B16,'Kachelofen'!$F:$F) | H16: =SUMIF('Gugelhupf'!$A:$A,$B16,'Gugelhupf'!$F:$F) | I16: =SUMIF('Lucia'!$A:$A,$B16,'Lucia'!$F:$F) | J16: =SUMIF('Bar'!$A:$A,$B16,'Bar'!$F:$F) | K16: =SUM(E16:J16)
